Workbook

Sheet ABRIL
F1: SUPER | G1: NIVEL | H1: TRABAJO | I1: DRENAR | J1: MEDICION BS2 | K1: AFORO FT | L1: A. INTERMITENTE | N1: SUPER | O1: NIVEL | P1: TRABAJO | Q1: DRENAR | R1: MEDICION BS2 | S1: AFORO FT | T1: A. INTERMITENTE | V1: SUPER | W1: NIVEL | X1: TRABAJO | Y1: DRENAR | Z1: MEDICION BS2 | AA1: AFORO FT | AB1: A. INTERMITENTE | AD1: SUPER | AE1: NIVEL | AF1: TRABAJO | AG1: DRENAR | AH1: MEDICION BS2 | AI1: AFORO FT | AJ1: A. INTERMITENTE | AL1: SUPER | AM1: NIVEL | AN1: TRABAJO | AO1: DRENAR | AP1: MEDICION BS2 | AQ1: AFORO FT | AR1: A. INTERMITENTE | AT1: SUPER | AU1: NIVEL | AV1: TRABAJO | AW1: DRENAR | AX1: MEDICION BS2 | AY1: AFORO FT | AZ1: A. INTERMITENTE | BB1: SUPER | BC1: NIVEL | BD1: TRABAJO | BE1: DRENAR | BF1: MEDICION BS2 | BG1: AFORO FT | BH1: A. INTERMITENTE | BJ1: SUPER | BK1: NIVEL | BL1: TRABAJO | BM1: DRENAR | BN1: MEDICION BS2 | BO1: AFORO FT | BP1: A. INTERMITENTE | BR1: SUPER | BS1: NIVEL | BT1: TRABAJO | BU1: DRENAR | BV1: MEDICION BS2 | BW1: AFORO FT | BX1: A. INTERMITENTE | BZ1: SUPER | CA1: NIVEL | CB1: TRABAJO | CC1: DRENAR | CD1: MEDICION BS2 | CE1: AFORO FT | CF1: A. INTERMITENTE | CH1: SUPER | CI1: NIVEL | CJ1: TRABAJO | CK1: DRENAR | CL1: MEDICION BS2 | CM1: AFORO FT | CN1: A. INTERMITENTE | CP1: SUPER | CQ1: NIVEL | CR1: TRABAJO | CS1: DRENAR | CT1: MEDICION BS2 | CU1: AFORO FT | CV1: A. INTERMITENTE | CX1: SUPER | CY1: NIVEL | CZ1: TRABAJO | DA1: DRENAR | DB1: MEDICION BS2 | DC1: AFORO FT | DD1: A. INTERMITENTE | DF1: SUPER | DG1: NIVEL | DH1: TRABAJO | DI1: DRENAR | DJ1: MEDICION BS2 | DK1: AFORO FT | DL1: A. INTERMITENTE | DN1: SUPER | DO1: NIVEL | DP1: TRABAJO | DQ1: DRENAR | DR1: MEDICION BS2 | DS1: AFORO FT | DT1: A. INTERMITENTE | DV1: SUPER | DW1: NIVEL | DX1: TRABAJO | DY1: DRENAR | DZ1: MEDICION BS2 | EA1: AFORO FT | EB1: A. INTERMITENTE | ED1: SUPER | EE1: NIVEL | EF1: TRABAJO | EG1: DRENAR | EH1: MEDICION BS2 | EI1: AFORO FT | EJ1: A. INTERMITENTE | EL1: SUPER | EM1: NIVEL | EN1: TRABAJO | EO1: DRENAR | EP1: MEDICION BS2 | EQ1: AFORO FT | ER1: A. INTERMITENTE | ET1: SUPER | EU1: NIVEL | EV1: TRABAJO | EW1: DRENAR | EX1: MEDICION BS2 | EY1: AFORO FT | EZ1: A. INTERMITENTE | FB1: SUPER | FC1: NIVEL | FD1: TRABAJO | FE1: DRENAR | FF1: MEDICION BS2 | FG1: AFORO FT | FH1: A. INTERMITENTE | FJ1: SUPER | FK1: NIVEL | FL1: TRABAJO | FM1: DRENAR | FN1: MEDICION BS2 | FO1: AFORO FT | FP1: A. INTERMITENTE | FR1: SUPER | FS1: NIVEL | FT1: TRABAJO | FU1: DRENAR | FV1: MEDICION BS2 | FW1: AFORO FT | FX1: A. INTERMITENTE | FZ1: SUPER | GA1: NIVEL | GB1: TRABAJO | GC1: DRENAR | GD1: MEDICION BS2 | GE1: AFORO FT | GF1: A. INTERMITENTE | GH1: SUPER | GI1: NIVEL | GJ1: TRABAJO | GK1: DRENAR | GL1: MEDICION BS2 | GM1: AFORO FT | GN1: A. INTERMITENTE | GP1: SUPER | GQ1: NIVEL | GR1: TRABAJO | GS1: DRENAR | GT1: MEDICION BS2 | GU1: AFORO FT | GV1: A. INTERMITENTE | GX1: SUPER | GY1: NIVEL | GZ1: TRABAJO | HA1: DRENAR | HB1: MEDICION BS2 | HC1: AFORO FT | HD1: A. INTERMITENTE | HF1: SUPER | HG1: NIVEL | HH1: TRABAJO | HI1: DRENAR | HJ1: MEDICION BS2 | HK1: AFORO FT | HL1: A. INTERMITENTE | HN1: SUPER | HO1: NIVEL | HP1: TRABAJO | HQ1: DRENAR | HR1: MEDICION BS2 | HS1: AFORO FT | HT1: A. INTERMITENTE | HV1: SUPER | HW1: NIVEL | HX1: TRABAJO | HY1: DRENAR | HZ1: MEDICION BS2 | IA1: AFORO FT | IB1: A. INTERMITENTE | ID1: SUPER | IE1: NIVEL | IF1: TRABAJO | IG1: DRENAR | IH1: MEDICION BS2 | II1: AFORO FT | IJ1: A. INTERMITENTE
B2: Fecha | C2: POZO | D2: ESTATUS | HN2: D | HU2: L | IC2: M
C3: CUICHAPA 106D | D3: OPERANDO | E3: 46174 | M3: =+E3+1 -> 46175 | N3: 2 | O3: 3 | U3: =+M3+1 -> 46176 | W3: 4 | AC3: =+U3+1 -> 46177 | AD3: 1 | AE3: 4 | AK3: =+AC3+1 -> 46178 | AL3: 1 | AM3: 4 | AS3: =+AK3+1 -> 46179 | AT3: 1 | AU3: 4 | BA3: =+AS3+1 -> 46180 | BB3: 1 | BC3: 3 | BI3: =+BA3+1 -> 46181 | BJ3: 1 | BK3: 3 | BQ3: =+BI3+1 -> 46182 | BR3: 1 | BS3: 3 | BY3: =+BQ3+1 -> 46183 | BZ3: 1 | CA3: 3 | CG3: =+BY3+1 -> 46184 | CH3: 1 | CI3: 3 | CO3: =+CG3+1 -> 46185 | CP3: 1 | CQ3: 3 | CW3: =+CO3+1 -> 46186 | CX3: 1 | CY3: 3 | DE3: =+CW3+1 -> 46187 | DF3: 1 | DG3: 3 | DM3: =+DE3+1 -> 46188 | DN3: 1 | DO3: 2 | DU3: =+DM3+1 -> 46189 | DV3: 1 | DW3: 2 | EC3: =+DU3+1 -> 46190 | ED3: 1 | EE3: 2 | EK3: =+EC3+1 -> 46191 | EL3: 1 | EM3: 2 | ES3: =+EK3+1 -> 46192 | ET3: 1 | EU3: 2 | FA3: =+ES3+1 -> 46193 | FI3: =+FA3+1 -> 46194 | FQ3: =+FI3+1 -> 46195 | FY3: =+FQ3+1 -> 46196 | GG3: =+FY3+1 -> 46197 | GO3: =+GG3+1 -> 46198 | GW3: =+GO3+1 -> 46199 | HE3: =+GW3+1 -> 46200 | HM3: =+HE3+1 -> 46201 | HU3: =+HM3+1 -> 46202 | IC3: =+HU3+1 -> 46203
C4: CUICHAPA 107 | D4: CERRADO | E4: =+E3 -> 46174 | M4: =+E4+1 -> 46175 | U4: =+M4+1 -> 46176 | AC4: =+U4+1 -> 46177 | AK4: =+AC4+1 -> 46178 | AS4: =+AK4+1 -> 46179 | BA4: =+AS4+1 -> 46180 | BI4: =+BA4+1 -> 46181 | BQ4: =+BI4+1 -> 46182 | BY4: =+BQ4+1 -> 46183 | CG4: =+BY4+1 -> 46184 | CO4: =+CG4+1 -> 46185 | CW4: =+CO4+1 -> 46186 | DE4: =+CW4+1 -> 46187 | DM4: =+DE4+1 -> 46188 | DU4: =+DM4+1 -> 46189 | EC4: =+DU4+1 -> 46190 | EK4: =+EC4+1 -> 46191 | ES4: =+EK4+1 -> 46192 | FA4: =+ES4+1 -> 46193 | FI4: =+FA4+1 -> 46194 | FQ4: =+FI4+1 -> 46195 | FY4: =+FQ4+1 -> 46196 | GG4: =+FY4+1 -> 46197 | GO4: =+GG4+1 -> 46198 | GW4: =+GO4+1 -> 46199 | HE4: =+GW4+1 -> 46200 | HM4: =+HE4+1 -> 46201 | HU4: =+HM4+1 -> 46202 | IC4: =+HU4+1 -> 46203
C5: CUICHAPA 119 | D5: CERRADO | E5: =+E4 -> 46174 | F5: 1 | M5: =+E5+1 -> 46175 | N5: 1 | U5: =+M5+1 -> 46176 | V5: 1 | AC5: =+U5+1 -> 46177 | AD5: 1 | AK5: =+AC5+1 -> 46178 | AL5: 1 | AS5: =+AK5+1 -> 46179 | AT5: 1 | BA5: =+AS5+1 -> 46180 | BB5: 1 | BI5: =+BA5+1 -> 46181 | BJ5: 1 | BQ5: =+BI5+1 -> 46182 | BR5: 1 | BY5: =+BQ5+1 -> 46183 | BZ5: 1 | CG5: =+BY5+1 -> 46184 | CH5: 1 | CO5: =+CG5+1 -> 46185 | CP5: 1 | CW5: =+CO5+1 -> 46186 | CX5: 1 | DE5: =+CW5+1 -> 46187 | DF5: 1 | DM5: =+DE5+1 -> 46188 | DN5: 1 | DU5: =+DM5+1 -> 46189 | DV5: 1 | EC5: =+DU5+1 -> 46190 | ED5: 1 | EK5: =+EC5+1 -> 46191 | EL5: 1 | ES5: =+EK5+1 -> 46192 | ET5: 1 | FA5: =+ES5+1 -> 46193 | FI5: =+FA5+1 -> 46194 | FQ5: =+FI5+1 -> 46195 | FY5: =+FQ5+1 -> 46196 | GG5: =+FY5+1 -> 46197 | GO5: =+GG5+1 -> 46198 | GW5: =+GO5+1 -> 46199 | HE5: =+GW5+1 -> 46200 | HM5: =+HE5+1 -> 46201 | HU5: =+HM5+1 -> 46202 | IC5: =+HU5+1 -> 46203
C6: CUICHAPA 124D | D6: CERRADO | E6: =+E5 -> 46174 | M6: =+E6+1 -> 46175 | U6: =+M6+1 -> 46176 | AC6: =+U6+1 -> 46177 | AK6: =+AC6+1 -> 46178 | AS6: =+AK6+1 -> 46179 | BA6: =+AS6+1 -> 46180 | BI6: =+BA6+1 -> 46181 | BQ6: =+BI6+1 -> 46182 | BY6: =+BQ6+1 -> 46183 | CG6: =+BY6+1 -> 46184 | CO6: =+CG6+1 -> 46185 | CW6: =+CO6+1 -> 46186 | DE6: =+CW6+1 -> 46187 | DM6: =+DE6+1 -> 46188 | DU6: =+DM6+1 -> 46189 | EC6: =+DU6+1 -> 46190 | EK6: =+EC6+1 -> 46191 | ES6: =+EK6+1 -> 46192 | FA6: =+ES6+1 -> 46193 | FI6: =+FA6+1 -> 46194 | FQ6: =+FI6+1 -> 46195 | FY6: =+FQ6+1 -> 46196 | GG6: =+FY6+1 -> 46197 | GO6: =+GG6+1 -> 46198 | GW6: =+GO6+1 -> 46199 | HE6: =+GW6+1 -> 46200 | HM6: =+HE6+1 -> 46201 | HU6: =+HM6+1 -> 46202 | IC6: =+HU6+1 -> 46203
C7: CUICHAPA 128 | D7: OPERANDO | E7: =+E6 -> 46174 | F7: 1 | M7: =+E7+1 -> 46175 | N7: 1 | U7: =+M7+1 -> 46176 | V7: 1 | AC7: =+U7+1 -> 46177 | AD7: 1 | AK7: =+AC7+1 -> 46178 | AL7: 1 | AS7: =+AK7+1 -> 46179 | AT7: 1 | BA7: =+AS7+1 -> 46180 | BB7: 1 | BI7: =+BA7+1 -> 46181 | BQ7: =+BI7+1 -> 46182 | BR7: 1 | BY7: =+BQ7+1 -> 46183 | BZ7: 1 | CG7: =+BY7+1 -> 46184 | CH7: 1 | CO7: =+CG7+1 -> 46185 | CP7: 1 | CW7: =+CO7+1 -> 46186 | CX7: 1 | DE7: =+CW7+1 -> 46187 | DF7: 1 | DM7: =+DE7+1 -> 46188 | DN7: 1 | DU7: =+DM7+1 -> 46189 | DV7: 1 | EC7: =+DU7+1 -> 46190 | ED7: 1 | EK7: =+EC7+1 -> 46191 | EL7: 1 | ES7: =+EK7+1 -> 46192 | ET7: 1 | FA7: =+ES7+1 -> 46193 | FI7: =+FA7+1 -> 46194 | FQ7: =+FI7+1 -> 46195 | FY7: =+FQ7+1 -> 46196 | GG7: =+FY7+1 -> 46197 | GO7: =+GG7+1 -> 46198 | GW7: =+GO7+1 -> 46199 | HE7: =+GW7+1 -> 46200 | HM7: =+HE7+1 -> 46201 | HU7: =+HM7+1 -> 46202 | IC7: =+HU7+1 -> 46203
C8: CUICHAPA 131 | D8: CERRADO | E8: =+E7 -> 46174 | F8: 1 | M8: =+E8+1 -> 46175 | N8: 1 | U8: =+M8+1 -> 46176 | V8: 2 | AC8: =+U8+1 -> 46177 | AD8: 1 | AK8: =+AC8+1 -> 46178 | AL8: 1 | AS8: =+AK8+1 -> 46179 | AT8: 1 | BA8: =+AS8+1 -> 46180 | BB8: 1 | BI8: =+BA8+1 -> 46181 | BQ8: =+BI8+1 -> 46182 | BR8: 1 | BY8: =+BQ8+1 -> 46183 | BZ8: 1 | CG8: =+BY8+1 -> 46184 | CH8: 1 | CO8: =+CG8+1 -> 46185 | CP8: 1 | CW8: =+CO8+1 -> 46186 | CX8: 1 | DE8: =+CW8+1 -> 46187 | DF8: 1 | DM8: =+DE8+1 -> 46188 | DN8: 1 | DU8: =+DM8+1 -> 46189 | DV8: 1 | EC8: =+DU8+1 -> 46190 | ED8: 1 | EK8: =+EC8+1 -> 46191 | ES8: =+EK8+1 -> 46192 | ET8: 1 | FA8: =+ES8+1 -> 46193 | FI8: =+FA8+1 -> 46194 | FQ8: =+FI8+1 -> 46195 | FY8: =+FQ8+1 -> 46196 | GG8: =+FY8+1 -> 46197 | GO8: =+GG8+1 -> 46198 | GW8: =+GO8+1 -> 46199 | HE8: =+GW8+1 -> 46200 | HM8: =+HE8+1 -> 46201 | HU8: =+HM8+1 -> 46202 | IC8: =+HU8+1 -> 46203
C9: CUICHAPA 137 | D9: CERRADO | E9: =+E8 -> 46174 | F9: 1 | G9: 1 | M9: =+E9+1 -> 46175 | N9: 2 | O9: 3 | U9: =+M9+1 -> 46176 | AC9: =+U9+1 -> 46177 | AD9: 1 | AE9: 1 | AK9: =+AC9+1 -> 46178 | AL9: 2 | AM9: 2 | AS9: =+AK9+1 -> 46179 | BA9: =+AS9+1 -> 46180 | BB9: 1 | BI9: =+BA9+1 -> 46181 | BQ9: =+BI9+1 -> 46182 | BY9: =+BQ9+1 -> 46183 | CG9: =+BY9+1 -> 46184 | CO9: =+CG9+1 -> 46185 | CW9: =+CO9+1 -> 46186 | DE9: =+CW9+1 -> 46187 | DF9: 1 | DG9: 1 | DM9: =+DE9+1 -> 46188 | DN9: 1 | DO9: 1 | DU9: =+DM9+1 -> 46189 | EC9: =+DU9+1 -> 46190 | EK9: =+EC9+1 -> 46191 | EL9: 1 | ES9: =+EK9+1 -> 46192 | EU9: 1 | FA9: =+ES9+1 -> 46193 | FI9: =+FA9+1 -> 46194 | FQ9: =+FI9+1 -> 46195 | FY9: =+FQ9+1 -> 46196 | GG9: =+FY9+1 -> 46197 | GO9: =+GG9+1 -> 46198 | GW9: =+GO9+1 -> 46199 | HE9: =+GW9+1 -> 46200 | HM9: =+HE9+1 -> 46201 | HU9: =+HM9+1 -> 46202 | IC9: =+HU9+1 -> 46203
C10: CUICHAPA 138 | D10: CERRADO | E10: =+E9 -> 46174 | M10: =+E10+1 -> 46175 | U10: =+M10+1 -> 46176 | AC10: =+U10+1 -> 46177 | AK10: =+AC10+1 -> 46178 | AS10: =+AK10+1 -> 46179 | BA10: =+AS10+1 -> 46180 | BI10: =+BA10+1 -> 46181 | BQ10: =+BI10+1 -> 46182 | BY10: =+BQ10+1 -> 46183 | CG10: =+BY10+1 -> 46184 | CO10: =+CG10+1 -> 46185 | CW10: =+CO10+1 -> 46186 | DE10: =+CW10+1 -> 46187 | DM10: =+DE10+1 -> 46188 | DU10: =+DM10+1 -> 46189 | EC10: =+DU10+1 -> 46190 | EK10: =+EC10+1 -> 46191 | ES10: =+EK10+1 -> 46192 | FA10: =+ES10+1 -> 46193 | FI10: =+FA10+1 -> 46194 | FQ10: =+FI10+1 -> 46195 | FY10: =+FQ10+1 -> 46196 | GG10: =+FY10+1 -> 46197 | GO10: =+GG10+1 -> 46198 | GW10: =+GO10+1 -> 46199 | HE10: =+GW10+1 -> 46200 | HM10: =+HE10+1 -> 46201 | HU10: =+HM10+1 -> 46202 | IC10: =+HU10+1 -> 46203
C11: CUICHAPA 139 | D11: CERRADO | E11: =+E10 -> 46174 | F11: 1 | G11: 3 | M11: =+E11+1 -> 46175 | N11: 1 | O11: 3 | U11: =+M11+1 -> 46176 | V11: 1 | W11: 2 | AC11: =+U11+1 -> 46177 | AD11: 1 | AE11: 5 | AK11: =+AC11+1 -> 46178 | AL11: 1 | AM11: 4 | AS11: =+AK11+1 -> 46179 | AT11: 1 | AU11: 3 | BA11: =+AS11+1 -> 46180 | BB11: 1 | BC11: 3 | BI11: =+BA11+1 -> 46181 | BJ11: 1 | BK11: 5 | BQ11: =+BI11+1 -> 46182 | BR11: 2 | BS11: 3 | BY11: =+BQ11+1 -> 46183 | BZ11: 1 | CA11: 3 | CG11: =+BY11+1 -> 46184 | CH11: 2 | CI11: 3 | CO11: =+CG11+1 -> 46185 | CP11: 1 | CQ11: 3 | CW11: =+CO11+1 -> 46186 | CX11: 1 | CY11: 3 | DE11: =+CW11+1 -> 46187 | DF11: 1 | DG11: 3 | DM11: =+DE11+1 -> 46188 | DN11: 1 | DO11: 2 | DU11: =+DM11+1 -> 46189 | DV11: 1 | DW11: 2 | EC11: =+DU11+1 -> 46190 | ED11: 1 | EE11: 2 | EK11: =+EC11+1 -> 46191 | EL11: 1 | EM11: 3 | ES11: =+EK11+1 -> 46192 | ET11: 1 | EU11: 2 | FA11: =+ES11+1 -> 46193 | FI11: =+FA11+1 -> 46194 | FQ11: =+FI11+1 -> 46195 | FY11: =+FQ11+1 -> 46196 | GG11: =+FY11+1 -> 46197 | GO11: =+GG11+1 -> 46198 | GW11: =+GO11+1 -> 46199 | HE11: =+GW11+1 -> 46200 | HM11: =+HE11+1 -> 46201 | HU11: =+HM11+1 -> 46202 | IC11: =+HU11+1 -> 46203
C12: CUICHAPA 167 | D12: OPERANDO | E12: =+E11 -> 46174 | F12: 1 | M12: =+E12+1 -> 46175 | N12: 1 | U12: =+M12+1 -> 46176 | V12: 1 | AC12: =+U12+1 -> 46177 | AD12: 1 | AK12: =+AC12+1 -> 46178 | AL12: 1 | AS12: =+AK12+1 -> 46179 | AT12: 1 | BA12: =+AS12+1 -> 46180 | BB12: 1 | BI12: =+BA12+1 -> 46181 | BJ12: 1 | BQ12: =+BI12+1 -> 46182 | BR12: 1 | BY12: =+BQ12+1 -> 46183 | BZ12: 1 | CG12: =+BY12+1 -> 46184 | CH12: 1 | CO12: =+CG12+1 -> 46185 | CP12: 1 | CW12: =+CO12+1 -> 46186 | CX12: 1 | DE12: =+CW12+1 -> 46187 | DF12: 1 | DM12: =+DE12+1 -> 46188 | DU12: =+DM12+1 -> 46189 | EC12: =+DU12+1 -> 46190 | EK12: =+EC12+1 -> 46191 | ES12: =+EK12+1 -> 46192 | FA12: =+ES12+1 -> 46193 | FI12: =+FA12+1 -> 46194 | FQ12: =+FI12+1 -> 46195 | FY12: =+FQ12+1 -> 46196 | GG12: =+FY12+1 -> 46197 | GO12: =+GG12+1 -> 46198 | GW12: =+GO12+1 -> 46199 | HE12: =+GW12+1 -> 46200 | HM12: =+HE12+1 -> 46201 | HU12: =+HM12+1 -> 46202 | IC12: =+HU12+1 -> 46203
C13: CUICHAPA 169 | D13: CERRADO | E13: =+E12 -> 46174 | M13: =+E13+1 -> 46175 | U13: =+M13+1 -> 46176 | AC13: =+U13+1 -> 46177 | AK13: =+AC13+1 -> 46178 | AS13: =+AK13+1 -> 46179 | BA13: =+AS13+1 -> 46180 | BI13: =+BA13+1 -> 46181 | BQ13: =+BI13+1 -> 46182 | BY13: =+BQ13+1 -> 46183 | CG13: =+BY13+1 -> 46184 | CO13: =+CG13+1 -> 46185 | CW13: =+CO13+1 -> 46186 | DE13: =+CW13+1 -> 46187 | DM13: =+DE13+1 -> 46188 | DU13: =+DM13+1 -> 46189 | EC13: =+DU13+1 -> 46190 | EK13: =+EC13+1 -> 46191 | ES13: =+EK13+1 -> 46192 | FA13: =+ES13+1 -> 46193 | FI13: =+FA13+1 -> 46194 | FQ13: =+FI13+1 -> 46195 | FY13: =+FQ13+1 -> 46196 | GG13: =+FY13+1 -> 46197 | GO13: =+GG13+1 -> 46198 | GW13: =+GO13+1 -> 46199 | HE13: =+GW13+1 -> 46200 | HM13: =+HE13+1 -> 46201 | HU13: =+HM13+1 -> 46202 | IC13: =+HU13+1 -> 46203
C14: CUICHAPA 172 | D14: OPERANDO | E14: =+E13 -> 46174 | F14: 1 | G14: 3 | M14: =+E14+1 -> 46175 | N14: 1 | O14: 1 | U14: =+M14+1 -> 46176 | W14: 1 | AC14: =+U14+1 -> 46177 | AD14: 1 | AE14: 3 | AK14: =+AC14+1 -> 46178 | AL14: 1 | AM14: 3 | AS14: =+AK14+1 -> 46179 | AU14: 4 | BA14: =+AS14+1 -> 46180 | BB14: 1 | BC14: 3 | BI14: =+BA14+1 -> 46181 | BJ14: 1 | BK14: 5 | BQ14: =+BI14+1 -> 46182 | BS14: 4 | BY14: =+BQ14+1 -> 46183 | CA14: 4 | CG14: =+BY14+1 -> 46184 | CI14: 4 | CO14: =+CG14+1 -> 46185 | CQ14: 2 | CW14: =+CO14+1 -> 46186 | CX14: 1 | CY14: 3 | DE14: =+CW14+1 -> 46187 | DF14: 1 | DG14: 4 | DM14: =+DE14+1 -> 46188 | DO14: 1 | DU14: =+DM14+1 -> 46189 | DW14: 1 | EC14: =+DU14+1 -> 46190 | EE14: 1 | EK14: =+EC14+1 -> 46191 | EM14: 1 | ES14: =+EK14+1 -> 46192 | EU14: 1 | FA14: =+ES14+1 -> 46193 | FI14: =+FA14+1 -> 46194 | FQ14: =+FI14+1 -> 46195 | FY14: =+FQ14+1 -> 46196 | GG14: =+FY14+1 -> 46197 | GO14: =+GG14+1 -> 46198 | GW14: =+GO14+1 -> 46199 | HE14: =+GW14+1 -> 46200 | HM14: =+HE14+1 -> 46201 | HU14: =+HM14+1 -> 46202 | IC14: =+HU14+1 -> 46203
C15: CUICHAPA 176 | D15: CERRADO | E15: =+E14 -> 46174 | M15: =+E15+1 -> 46175 | U15: =+M15+1 -> 46176 | AC15: =+U15+1 -> 46177 | AK15: =+AC15+1 -> 46178 | AS15: =+AK15+1 -> 46179 | BA15: =+AS15+1 -> 46180 | BI15: =+BA15+1 -> 46181 | BQ15: =+BI15+1 -> 46182 | BY15: =+BQ15+1 -> 46183 | CG15: =+BY15+1 -> 46184 | CO15: =+CG15+1 -> 46185 | CW15: =+CO15+1 -> 46186 | DE15: =+CW15+1 -> 46187 | DM15: =+DE15+1 -> 46188 | DU15: =+DM15+1 -> 46189 | EC15: =+DU15+1 -> 46190 | EK15: =+EC15+1 -> 46191 | ES15: =+EK15+1 -> 46192 | FA15: =+ES15+1 -> 46193 | FI15: =+FA15+1 -> 46194 | FQ15: =+FI15+1 -> 46195 | FY15: =+FQ15+1 -> 46196 | GG15: =+FY15+1 -> 46197 | GO15: =+GG15+1 -> 46198 | GW15: =+GO15+1 -> 46199 | HE15: =+GW15+1 -> 46200 | HM15: =+HE15+1 -> 46201 | HU15: =+HM15+1 -> 46202 | IC15: =+HU15+1 -> 46203
C16: CUICHAPA 179 | D16: OPERANDO | E16: =+E15 -> 46174 | F16: 1 | G16: 3 | M16: =+E16+1 -> 46175 | N16: 1 | O16: 3 | U16: =+M16+1 -> 46176 | W16: 2 | AC16: =+U16+1 -> 46177 | AD16: 1 | AE16: 3 | AK16: =+AC16+1 -> 46178 | AL16: 1 | AM16: 3 | AS16: =+AK16+1 -> 46179 | AT16: 1 | AU16: 3 | BA16: =+AS16+1 -> 46180 | BB16: 1 | BC16: 3 | BI16: =+BA16+1 -> 46181 | BK16: 2 | BQ16: =+BI16+1 -> 46182 | BR16: 1 | BS16: 3 | BY16: =+BQ16+1 -> 46183 | BZ16: 1 | CA16: 3 | CG16: =+BY16+1 -> 46184 | CH16: 1 | CI16: 3 | CO16: =+CG16+1 -> 46185 | CP16: 1 | CQ16: 3 | CW16: =+CO16+1 -> 46186 | CX16: 1 | CY16: 3 | DE16: =+CW16+1 -> 46187 | DF16: 1 | DG16: 3 | DM16: =+DE16+1 -> 46188 | DN16: 1 | DO16: 2 | DU16: =+DM16+1 -> 46189 | DW16: 2 | EC16: =+DU16+1 -> 46190 | ED16: 1 | EE16: 2 | EK16: =+EC16+1 -> 46191 | EL16: 1 | EM16: 2 | ES16: =+EK16+1 -> 46192 | ET16: 1 | EU16: 2 | FA16: =+ES16+1 -> 46193 | FI16: =+FA16+1 -> 46194 | FQ16: =+FI16+1 -> 46195 | FY16: =+FQ16+1 -> 46196 | GG16: =+FY16+1 -> 46197 | GO16: =+GG16+1 -> 46198 | GW16: =+GO16+1 -> 46199 | HE16: =+GW16+1 -> 46200 | HM16: =+HE16+1 -> 46201 | HU16: =+HM16+1 -> 46202 | IC16: =+HU16+1 -> 46203
C17: CUICHAPA 180 | D17: CERRADO | E17: =+E16 -> 46174 | M17: =+E17+1 -> 46175 | U17: =+M17+1 -> 46176 | AC17: =+U17+1 -> 46177 | AK17: =+AC17+1 -> 46178 | AS17: =+AK17+1 -> 46179 | BA17: =+AS17+1 -> 46180 | BI17: =+BA17+1 -> 46181 | BQ17: =+BI17+1 -> 46182 | BY17: =+BQ17+1 -> 46183 | CG17: =+BY17+1 -> 46184 | CO17: =+CG17+1 -> 46185 | CW17: =+CO17+1 -> 46186 | DE17: =+CW17+1 -> 46187 | DM17: =+DE17+1 -> 46188 | DU17: =+DM17+1 -> 46189 | EC17: =+DU17+1 -> 46190 | EK17: =+EC17+1 -> 46191 | ES17: =+EK17+1 -> 46192 | FA17: =+ES17+1 -> 46193 | FI17: =+FA17+1 -> 46194 | FQ17: =+FI17+1 -> 46195 | FY17: =+FQ17+1 -> 46196 | GG17: =+FY17+1 -> 46197 | GO17: =+GG17+1 -> 46198 | GW17: =+GO17+1 -> 46199 | HE17: =+GW17+1 -> 46200 | HM17: =+HE17+1 -> 46201 | HU17: =+HM17+1 -> 46202 | IC17: =+HU17+1 -> 46203
C18: CUICHAPA 187 | D18: CERRADO | E18: =+E17 -> 46174 | F18: 1 | M18: =+E18+1 -> 46175 | N18: 1 | U18: =+M18+1 -> 46176 | V18: 1 | AC18: =+U18+1 -> 46177 | AK18: =+AC18+1 -> 46178 | AL18: 1 | AS18: =+AK18+1 -> 46179 | AT18: 1 | BA18: =+AS18+1 -> 46180 | BB18: 1 | BI18: =+BA18+1 -> 46181 | BJ18: 1 | BQ18: =+BI18+1 -> 46182 | BR18: 1 | BY18: =+BQ18+1 -> 46183 | BZ18: 1 | CG18: =+BY18+1 -> 46184 | CH18: 1 | CO18: =+CG18+1 -> 46185 | CW18: =+CO18+1 -> 46186 | CX18: 1 | DE18: =+CW18+1 -> 46187 | DF18: 1 | DM18: =+DE18+1 -> 46188 | DU18: =+DM18+1 -> 46189 | EC18: =+DU18+1 -> 46190 | EK18: =+EC18+1 -> 46191 | ES18: =+EK18+1 -> 46192 | FA18: =+ES18+1 -> 46193 | FI18: =+FA18+1 -> 46194 | FQ18: =+FI18+1 -> 46195 | FY18: =+FQ18+1 -> 46196 | GG18: =+FY18+1 -> 46197 | GO18: =+GG18+1 -> 46198 | GW18: =+GO18+1 -> 46199 | HE18: =+GW18+1 -> 46200 | HM18: =+HE18+1 -> 46201 | HU18: =+HM18+1 -> 46202 | IC18: =+HU18+1 -> 46203
C19: CUICHAPA 19 | D19: CERRADO | E19: =+E18 -> 46174 | M19: =+E19+1 -> 46175 | U19: =+M19+1 -> 46176 | AC19: =+U19+1 -> 46177 | AK19: =+AC19+1 -> 46178 | AS19: =+AK19+1 -> 46179 | BA19: =+AS19+1 -> 46180 | BB19: 1 | BI19: =+BA19+1 -> 46181 | BQ19: =+BI19+1 -> 46182 | BY19: =+BQ19+1 -> 46183 | CG19: =+BY19+1 -> 46184 | CO19: =+CG19+1 -> 46185 | CP19: 1 | CW19: =+CO19+1 -> 46186 | CX19: 1 | DE19: =+CW19+1 -> 46187 | DM19: =+DE19+1 -> 46188 | DN19: 1 | DU19: =+DM19+1 -> 46189 | EC19: =+DU19+1 -> 46190 | ED19: 1 | EK19: =+EC19+1 -> 46191 | EL19: 1 | ES19: =+EK19+1 -> 46192 | ET19: 1 | FA19: =+ES19+1 -> 46193 | FI19: =+FA19+1 -> 46194 | FQ19: =+FI19+1 -> 46195 | FY19: =+FQ19+1 -> 46196 | GG19: =+FY19+1 -> 46197 | GO19: =+GG19+1 -> 46198 | GW19: =+GO19+1 -> 46199 | HE19: =+GW19+1 -> 46200 | HM19: =+HE19+1 -> 46201 | HU19: =+HM19+1 -> 46202 | IC19: =+HU19+1 -> 46203
C20: CUICHAPA 191 | D20: OPERANDO | E20: =+E19 -> 46174 | F20: 1 | M20: =+E20+1 -> 46175 | N20: 1 | U20: =+M20+1 -> 46176 | V20: 1 | AC20: =+U20+1 -> 46177 | AD20: 1 | AK20: =+AC20+1 -> 46178 | AL20: 1 | AS20: =+AK20+1 -> 46179 | AT20: 1 | BA20: =+AS20+1 -> 46180 | BB20: 1 | BI20: =+BA20+1 -> 46181 | BJ20: 1 | BQ20: =+BI20+1 -> 46182 | BR20: 1 | BY20: =+BQ20+1 -> 46183 | BZ20: 1 | CG20: =+BY20+1 -> 46184 | CH20: 1 | CO20: =+CG20+1 -> 46185 | CW20: =+CO20+1 -> 46186 | CX20: 1 | DE20: =+CW20+1 -> 46187 | DF20: 1 | DM20: =+DE20+1 -> 46188 | DU20: =+DM20+1 -> 46189 | EC20: =+DU20+1 -> 46190 | EK20: =+EC20+1 -> 46191 | ES20: =+EK20+1 -> 46192 | FA20: =+ES20+1 -> 46193 | FI20: =+FA20+1 -> 46194 | FQ20: =+FI20+1 -> 46195 | FY20: =+FQ20+1 -> 46196 | GG20: =+FY20+1 -> 46197 | GO20: =+GG20+1 -> 46198 | GW20: =+GO20+1 -> 46199 | HE20: =+GW20+1 -> 46200 | HM20: =+HE20+1 -> 46201 | HU20: =+HM20+1 -> 46202 | IC20: =+HU20+1 -> 46203
C21: CUICHAPA 201 | D21: CERRADO | E21: =+E20 -> 46174 | M21: =+E21+1 -> 46175 | N21: 1 | U21: =+M21+1 -> 46176 | AC21: =+U21+1 -> 46177 | AK21: =+AC21+1 -> 46178 | AM21: 6 | AS21: =+AK21+1 -> 46179 | BA21: =+AS21+1 -> 46180 | BI21: =+BA21+1 -> 46181 | BQ21: =+BI21+1 -> 46182 | BY21: =+BQ21+1 -> 46183 | CG21: =+BY21+1 -> 46184 | CO21: =+CG21+1 -> 46185 | CW21: =+CO21+1 -> 46186 | DE21: =+CW21+1 -> 46187 | DM21: =+DE21+1 -> 46188 | DU21: =+DM21+1 -> 46189 | EC21: =+DU21+1 -> 46190 | EK21: =+EC21+1 -> 46191 | ES21: =+EK21+1 -> 46192 | FA21: =+ES21+1 -> 46193 | FI21: =+FA21+1 -> 46194 | FQ21: =+FI21+1 -> 46195 | FY21: =+FQ21+1 -> 46196 | GG21: =+FY21+1 -> 46197 | GO21: =+GG21+1 -> 46198 | GW21: =+GO21+1 -> 46199 | HE21: =+GW21+1 -> 46200 | HM21: =+HE21+1 -> 46201 | HU21: =+HM21+1 -> 46202 | IC21: =+HU21+1 -> 46203
C22: CUICHAPA 207 | D22: CERRADO | E22: =+E21 -> 46174 | M22: =+E22+1 -> 46175 | U22: =+M22+1 -> 46176 | AC22: =+U22+1 -> 46177 | AK22: =+AC22+1 -> 46178 | AS22: =+AK22+1 -> 46179 | BA22: =+AS22+1 -> 46180 | BI22: =+BA22+1 -> 46181 | BQ22: =+BI22+1 -> 46182 | BY22: =+BQ22+1 -> 46183 | CG22: =+BY22+1 -> 46184 | CO22: =+CG22+1 -> 46185 | CW22: =+CO22+1 -> 46186 | DE22: =+CW22+1 -> 46187 | DM22: =+DE22+1 -> 46188 | DU22: =+DM22+1 -> 46189 | EC22: =+DU22+1 -> 46190 | EK22: =+EC22+1 -> 46191 | ES22: =+EK22+1 -> 46192 | FA22: =+ES22+1 -> 46193 | FI22: =+FA22+1 -> 46194 | FQ22: =+FI22+1 -> 46195 | FY22: =+FQ22+1 -> 46196 | GG22: =+FY22+1 -> 46197 | GO22: =+GG22+1 -> 46198 | GW22: =+GO22+1 -> 46199 | HE22: =+GW22+1 -> 46200 | HM22: =+HE22+1 -> 46201 | HU22: =+HM22+1 -> 46202 | IC22: =+HU22+1 -> 46203
C23: CUICHAPA 213 | D23: OPERANDO | E23: =+E22 -> 46174 | F23: 1 | M23: =+E23+1 -> 46175 | N23: 1 | U23: =+M23+1 -> 46176 | AC23: =+U23+1 -> 46177 | AD23: 1 | AK23: =+AC23+1 -> 46178 | AS23: =+AK23+1 -> 46179 | BA23: =+AS23+1 -> 46180 | BB23: 1 | BI23: =+BA23+1 -> 46181 | BQ23: =+BI23+1 -> 46182 | BY23: =+BQ23+1 -> 46183 | BZ23: 1 | CG23: =+BY23+1 -> 46184 | CH23: 1 | CO23: =+CG23+1 -> 46185 | CW23: =+CO23+1 -> 46186 | CX23: 1 | DE23: =+CW23+1 -> 46187 | DF23: 1 | DM23: =+DE23+1 -> 46188 | DU23: =+DM23+1 -> 46189 | EC23: =+DU23+1 -> 46190 | EK23: =+EC23+1 -> 46191 | ES23: =+EK23+1 -> 46192 | FA23: =+ES23+1 -> 46193 | FI23: =+FA23+1 -> 46194 | FQ23: =+FI23+1 -> 46195 | FY23: =+FQ23+1 -> 46196 | GG23: =+FY23+1 -> 46197 | GO23: =+GG23+1 -> 46198 | GW23: =+GO23+1 -> 46199 | HE23: =+GW23+1 -> 46200 | HM23: =+HE23+1 -> 46201 | HU23: =+HM23+1 -> 46202 | IC23: =+HU23+1 -> 46203
C24: CUICHAPA 306 | D24: CERRADO | E24: =+E23 -> 46174 | M24: =+E24+1 -> 46175 | U24: =+M24+1 -> 46176 | AC24: =+U24+1 -> 46177 | AK24: =+AC24+1 -> 46178 | AS24: =+AK24+1 -> 46179 | BA24: =+AS24+1 -> 46180 | BI24: =+BA24+1 -> 46181 | BQ24: =+BI24+1 -> 46182 | BY24: =+BQ24+1 -> 46183 | CG24: =+BY24+1 -> 46184 | CO24: =+CG24+1 -> 46185 | CW24: =+CO24+1 -> 46186 | DE24: =+CW24+1 -> 46187 | DM24: =+DE24+1 -> 46188 | DU24: =+DM24+1 -> 46189 | EC24: =+DU24+1 -> 46190 | EK24: =+EC24+1 -> 46191 | ES24: =+EK24+1 -> 46192 | FA24: =+ES24+1 -> 46193 | FI24: =+FA24+1 -> 46194 | FQ24: =+FI24+1 -> 46195 | FY24: =+FQ24+1 -> 46196 | GG24: =+FY24+1 -> 46197 | GO24: =+GG24+1 -> 46198 | GW24: =+GO24+1 -> 46199 | HE24: =+GW24+1 -> 46200 | HM24: =+HE24+1 -> 46201 | HU24: =+HM24+1 -> 46202 | IC24: =+HU24+1 -> 46203
C25: CUICHAPA 324 | D25: CERRADO | E25: =+E24 -> 46174 | M25: =+E25+1 -> 46175 | U25: =+M25+1 -> 46176 | AC25: =+U25+1 -> 46177 | AK25: =+AC25+1 -> 46178 | AL25: 1 | AS25: =+AK25+1 -> 46179 | BA25: =+AS25+1 -> 46180 | BI25: =+BA25+1 -> 46181 | BQ25: =+BI25+1 -> 46182 | BY25: =+BQ25+1 -> 46183 | BZ25: 1 | CG25: =+BY25+1 -> 46184 | CH25: 1 | CO25: =+CG25+1 -> 46185 | CP25: 1 | CW25: =+CO25+1 -> 46186 | CX25: 1 | DE25: =+CW25+1 -> 46187 | DF25: 1 | DM25: =+DE25+1 -> 46188 | DN25: 1 | DU25: =+DM25+1 -> 46189 | DV25: 1 | EC25: =+DU25+1 -> 46190 | ED25: 1 | EK25: =+EC25+1 -> 46191 | EL25: 1 | ES25: =+EK25+1 -> 46192 | ET25: 1 | FA25: =+ES25+1 -> 46193 | FI25: =+FA25+1 -> 46194 | FQ25: =+FI25+1 -> 46195 | FY25: =+FQ25+1 -> 46196 | GG25: =+FY25+1 -> 46197 | GO25: =+GG25+1 -> 46198 | GW25: =+GO25+1 -> 46199 | HE25: =+GW25+1 -> 46200 | HM25: =+HE25+1 -> 46201 | HU25: =+HM25+1 -> 46202 | IC25: =+HU25+1 -> 46203
C26: CUICHAPA 326 | D26: OPERANDO | E26: =+E25 -> 46174 | F26: 1 | M26: =+E26+1 -> 46175 | N26: 1 | U26: =+M26+1 -> 46176 | V26: 1 | AC26: =+U26+1 -> 46177 | AD26: 1 | AK26: =+AC26+1 -> 46178 | AL26: 1 | AS26: =+AK26+1 -> 46179 | AT26: 1 | BA26: =+AS26+1 -> 46180 | BI26: =+BA26+1 -> 46181 | BJ26: 1 | BQ26: =+BI26+1 -> 46182 | BY26: =+BQ26+1 -> 46183 | BZ26: 1 | CG26: =+BY26+1 -> 46184 | CH26: 1 | CO26: =+CG26+1 -> 46185 | CP26: 1 | CW26: =+CO26+1 -> 46186 | CX26: 1 | DE26: =+CW26+1 -> 46187 | DF26: 1 | DM26: =+DE26+1 -> 46188 | DN26: 1 | DU26: =+DM26+1 -> 46189 | DV26: 1 | EC26: =+DU26+1 -> 46190 | ED26: 1 | EK26: =+EC26+1 -> 46191 | EL26: 1 | ES26: =+EK26+1 -> 46192 | EU26: 1 | FA26: =+ES26+1 -> 46193 | FI26: =+FA26+1 -> 46194 | FQ26: =+FI26+1 -> 46195 | FY26: =+FQ26+1 -> 46196 | GG26: =+FY26+1 -> 46197 | GO26: =+GG26+1 -> 46198 | GW26: =+GO26+1 -> 46199 | HE26: =+GW26+1 -> 46200 | HM26: =+HE26+1 -> 46201 | HU26: =+HM26+1 -> 46202 | IC26: =+HU26+1 -> 46203
C27: CUICHAPA 327 | D27: OPERANDO | E27: =+E26 -> 46174 | F27: 1 | M27: =+E27+1 -> 46175 | N27: 1 | U27: =+M27+1 -> 46176 | AC27: =+U27+1 -> 46177 | AD27: 1 | AK27: =+AC27+1 -> 46178 | AL27: 1 | AS27: =+AK27+1 -> 46179 | AT27: 1 | BA27: =+AS27+1 -> 46180 | BB27: 1 | BI27: =+BA27+1 -> 46181 | BJ27: 1 | BQ27: =+BI27+1 -> 46182 | BY27: =+BQ27+1 -> 46183 | BZ27: 1 | CG27: =+BY27+1 -> 46184 | CH27: 1 | CO27: =+CG27+1 -> 46185 | CP27: 1 | CW27: =+CO27+1 -> 46186 | CX27: 1 | DE27: =+CW27+1 -> 46187 | DF27: 1 | DM27: =+DE27+1 -> 46188 | DN27: 1 | DU27: =+DM27+1 -> 46189 | DV27: 1 | EC27: =+DU27+1 -> 46190 | ED27: 1 | EK27: =+EC27+1 -> 46191 | EL27: 1 | ES27: =+EK27+1 -> 46192 | FA27: =+ES27+1 -> 46193 | FI27: =+FA27+1 -> 46194 | FQ27: =+FI27+1 -> 46195 | FY27: =+FQ27+1 -> 46196 | GG27: =+FY27+1 -> 46197 | GO27: =+GG27+1 -> 46198 | GW27: =+GO27+1 -> 46199 | HE27: =+GW27+1 -> 46200 | HM27: =+HE27+1 -> 46201 | HU27: =+HM27+1 -> 46202 | IC27: =+HU27+1 -> 46203
C28: CUICHAPA 328 | D28: CERRADO | E28: =+E27 -> 46174 | F28: 2 | M28: =+E28+1 -> 46175 | N28: 1 | U28: =+M28+1 -> 46176 | V28: 2 | AC28: =+U28+1 -> 46177 | AD28: 1 | AK28: =+AC28+1 -> 46178 | AL28: 1 | AS28: =+AK28+1 -> 46179 | AT28: 1 | BA28: =+AS28+1 -> 46180 | BB28: 1 | BI28: =+BA28+1 -> 46181 | BQ28: =+BI28+1 -> 46182 | BR28: 4 | BY28: =+BQ28+1 -> 46183 | BZ28: 1 | CG28: =+BY28+1 -> 46184 | CH28: 2 | CO28: =+CG28+1 -> 46185 | CP28: 1 | CW28: =+CO28+1 -> 46186 | CX28: 1 | DE28: =+CW28+1 -> 46187 | DF28: 1 | DM28: =+DE28+1 -> 46188 | DN28: 1 | DU28: =+DM28+1 -> 46189 | DV28: 1 | EC28: =+DU28+1 -> 46190 | ED28: 1 | EK28: =+EC28+1 -> 46191 | EL28: 1 | ES28: =+EK28+1 -> 46192 | ET28: 1 | FA28: =+ES28+1 -> 46193 | FI28: =+FA28+1 -> 46194 | FQ28: =+FI28+1 -> 46195 | FY28: =+FQ28+1 -> 46196 | GG28: =+FY28+1 -> 46197 | GO28: =+GG28+1 -> 46198 | GW28: =+GO28+1 -> 46199 | HE28: =+GW28+1 -> 46200 | HM28: =+HE28+1 -> 46201 | HU28: =+HM28+1 -> 46202 | IC28: =+HU28+1 -> 46203
C29: CUICHAPA 331 | D29: CERRADO | E29: =+E28 -> 46174 | M29: =+E29+1 -> 46175 | U29: =+M29+1 -> 46176 | AC29: =+U29+1 -> 46177 | AK29: =+AC29+1 -> 46178 | AS29: =+AK29+1 -> 46179 | BA29: =+AS29+1 -> 46180 | BI29: =+BA29+1 -> 46181 | BQ29: =+BI29+1 -> 46182 | BY29: =+BQ29+1 -> 46183 | CG29: =+BY29+1 -> 46184 | CO29: =+CG29+1 -> 46185 | CW29: =+CO29+1 -> 46186 | DE29: =+CW29+1 -> 46187 | DM29: =+DE29+1 -> 46188 | DU29: =+DM29+1 -> 46189 | EC29: =+DU29+1 -> 46190 | EK29: =+EC29+1 -> 46191 | ES29: =+EK29+1 -> 46192 | FA29: =+ES29+1 -> 46193 | FI29: =+FA29+1 -> 46194 | FQ29: =+FI29+1 -> 46195 | FY29: =+FQ29+1 -> 46196 | GG29: =+FY29+1 -> 46197 | GO29: =+GG29+1 -> 46198 | GW29: =+GO29+1 -> 46199 | HE29: =+GW29+1 -> 46200 | HM29: =+HE29+1 -> 46201 | HU29: =+HM29+1 -> 46202 | IC29: =+HU29+1 -> 46203
C30: CUICHAPA 342 | D30: OPERANDO | E30: =+E29 -> 46174 | F30: 1 | M30: =+E30+1 -> 46175 | N30: 2 | U30: =+M30+1 -> 46176 | AC30: =+U30+1 -> 46177 | AD30: 1 | AK30: =+AC30+1 -> 46178 | AL30: 1 | AS30: =+AK30+1 -> 46179 | AT30: 1 | BA30: =+AS30+1 -> 46180 | BB30: 1 | BI30: =+BA30+1 -> 46181 | BJ30: 1 | BQ30: =+BI30+1 -> 46182 | BR30: 1 | BY30: =+BQ30+1 -> 46183 | BZ30: 1 | CG30: =+BY30+1 -> 46184 | CO30: =+CG30+1 -> 46185 | CW30: =+CO30+1 -> 46186 | CX30: 1 | DE30: =+CW30+1 -> 46187 | DF30: 1 | DM30: =+DE30+1 -> 46188 | DU30: =+DM30+1 -> 46189 | EC30: =+DU30+1 -> 46190 | EK30: =+EC30+1 -> 46191 | ES30: =+EK30+1 -> 46192 | FA30: =+ES30+1 -> 46193 | FI30: =+FA30+1 -> 46194 | FQ30: =+FI30+1 -> 46195 | FY30: =+FQ30+1 -> 46196 | GG30: =+FY30+1 -> 46197 | GO30: =+GG30+1 -> 46198 | GW30: =+GO30+1 -> 46199 | HE30: =+GW30+1 -> 46200 | HM30: =+HE30+1 -> 46201 | HU30: =+HM30+1 -> 46202 | IC30: =+HU30+1 -> 46203
C31: CUICHAPA 343 | D31: CERRADO | E31: =+E30 -> 46174 | M31: =+E31+1 -> 46175 | U31: =+M31+1 -> 46176 | AC31: =+U31+1 -> 46177 | AK31: =+AC31+1 -> 46178 | AS31: =+AK31+1 -> 46179 | BA31: =+AS31+1 -> 46180 | BI31: =+BA31+1 -> 46181 | BQ31: =+BI31+1 -> 46182 | BY31: =+BQ31+1 -> 46183 | CG31: =+BY31+1 -> 46184 | CO31: =+CG31+1 -> 46185 | CW31: =+CO31+1 -> 46186 | DE31: =+CW31+1 -> 46187 | DM31: =+DE31+1 -> 46188 | DU31: =+DM31+1 -> 46189 | EC31: =+DU31+1 -> 46190 | EK31: =+EC31+1 -> 46191 | ES31: =+EK31+1 -> 46192 | FA31: =+ES31+1 -> 46193 | FI31: =+FA31+1 -> 46194 | FQ31: =+FI31+1 -> 46195 | FY31: =+FQ31+1 -> 46196 | GG31: =+FY31+1 -> 46197 | GO31: =+GG31+1 -> 46198 | GW31: =+GO31+1 -> 46199 | HE31: =+GW31+1 -> 46200 | HM31: =+HE31+1 -> 46201 | HU31: =+HM31+1 -> 46202 | IC31: =+HU31+1 -> 46203
C32: CUICHAPA 346 | D32: OPERANDO | E32: =+E31 -> 46174 | F32: 1 | M32: =+E32+1 -> 46175 | N32: 1 | U32: =+M32+1 -> 46176 | AC32: =+U32+1 -> 46177 | AD32: 1 | AK32: =+AC32+1 -> 46178 | AL32: 1 | AS32: =+AK32+1 -> 46179 | AT32: 1 | BA32: =+AS32+1 -> 46180 | BB32: 1 | BI32: =+BA32+1 -> 46181 | BJ32: 1 | BQ32: =+BI32+1 -> 46182 | BR32: 1 | BY32: =+BQ32+1 -> 46183 | BZ32: 1 | CG32: =+BY32+1 -> 46184 | CO32: =+CG32+1 -> 46185 | CP32: 1 | CW32: =+CO32+1 -> 46186 | DE32: =+CW32+1 -> 46187 | DF32: 1 | DM32: =+DE32+1 -> 46188 | DU32: =+DM32+1 -> 46189 | EC32: =+DU32+1 -> 46190 | EK32: =+EC32+1 -> 46191 | ES32: =+EK32+1 -> 46192 | FA32: =+ES32+1 -> 46193 | FI32: =+FA32+1 -> 46194 | FQ32: =+FI32+1 -> 46195 | FY32: =+FQ32+1 -> 46196 | GG32: =+FY32+1 -> 46197 | GO32: =+GG32+1 -> 46198 | GW32: =+GO32+1 -> 46199 | HE32: =+GW32+1 -> 46200 | HM32: =+HE32+1 -> 46201 | HU32: =+HM32+1 -> 46202 | IC32: =+HU32+1 -> 46203
C33: CUICHAPA 350 | D33: OPERANDO | E33: =+E32 -> 46174 | F33: 1 | M33: =+E33+1 -> 46175 | N33: 1 | U33: =+M33+1 -> 46176 | AC33: =+U33+1 -> 46177 | AK33: =+AC33+1 -> 46178 | AL33: 1 | AS33: =+AK33+1 -> 46179 | AT33: 1 | BA33: =+AS33+1 -> 46180 | BI33: =+BA33+1 -> 46181 | BJ33: 1 | BQ33: =+BI33+1 -> 46182 | BR33: 1 | BY33: =+BQ33+1 -> 46183 | BZ33: 1 | CG33: =+BY33+1 -> 46184 | CH33: 1 | CO33: =+CG33+1 -> 46185 | CP33: 1 | CW33: =+CO33+1 -> 46186 | CX33: 1 | DE33: =+CW33+1 -> 46187 | DF33: 1 | DM33: =+DE33+1 -> 46188 | DU33: =+DM33+1 -> 46189 | EC33: =+DU33+1 -> 46190 | EK33: =+EC33+1 -> 46191 | ES33: =+EK33+1 -> 46192 | FA33: =+ES33+1 -> 46193 | FI33: =+FA33+1 -> 46194 | FQ33: =+FI33+1 -> 46195 | FY33: =+FQ33+1 -> 46196 | GG33: =+FY33+1 -> 46197 | GO33: =+GG33+1 -> 46198 | GW33: =+GO33+1 -> 46199 | HE33: =+GW33+1 -> 46200 | HM33: =+HE33+1 -> 46201 | HU33: =+HM33+1 -> 46202 | IC33: =+HU33+1 -> 46203
C34: CUICHAPA 352 | D34: CERRADO | E34: =+E33 -> 46174 | F34: 1 | G34: 3 | M34: =+E34+1 -> 46175 | N34: 1 | O34: 2 | U34: =+M34+1 -> 46176 | V34: 1 | W34: 2 | AC34: =+U34+1 -> 46177 | AD34: 1 | AE34: 4 | AK34: =+AC34+1 -> 46178 | AL34: 1 | AM34: 3 | AS34: =+AK34+1 -> 46179 | AT34: 2 | AU34: 3 | BA34: =+AS34+1 -> 46180 | BI34: =+BA34+1 -> 46181 | BQ34: =+BI34+1 -> 46182 | BR34: 2 | BS34: 4 | BY34: =+BQ34+1 -> 46183 | BZ34: 1 | CA34: 3 | CG34: =+BY34+1 -> 46184 | CH34: 1 | CI34: 3 | CO34: =+CG34+1 -> 46185 | CQ34: 2 | CW34: =+CO34+1 -> 46186 | CX34: 1 | CY34: 3 | DE34: =+CW34+1 -> 46187 | DF34: 1 | DG34: 3 | DM34: =+DE34+1 -> 46188 | DO34: 1 | DU34: =+DM34+1 -> 46189 | DW34: 1 | EC34: =+DU34+1 -> 46190 | EE34: 1 | EK34: =+EC34+1 -> 46191 | EM34: 1 | ES34: =+EK34+1 -> 46192 | EU34: 1 | FA34: =+ES34+1 -> 46193 | FI34: =+FA34+1 -> 46194 | FQ34: =+FI34+1 -> 46195 | FY34: =+FQ34+1 -> 46196 | GG34: =+FY34+1 -> 46197 | GO34: =+GG34+1 -> 46198 | GW34: =+GO34+1 -> 46199 | HE34: =+GW34+1 -> 46200 | HM34: =+HE34+1 -> 46201 | HU34: =+HM34+1 -> 46202 | IC34: =+HU34+1 -> 46203
C35: CUICHAPA 356 | D35: CERRADO | E35: =+E34 -> 46174 | M35: =+E35+1 -> 46175 | N35: 1 | U35: =+M35+1 -> 46176 | V35: 1 | AC35: =+U35+1 -> 46177 | AK35: =+AC35+1 -> 46178 | AS35: =+AK35+1 -> 46179 | AT35: 2 | BA35: =+AS35+1 -> 46180 | BI35: =+BA35+1 -> 46181 | BJ35: 1 | BQ35: =+BI35+1 -> 46182 | BR35: 1 | BY35: =+BQ35+1 -> 46183 | CG35: =+BY35+1 -> 46184 | CO35: =+CG35+1 -> 46185 | CW35: =+CO35+1 -> 46186 | DE35: =+CW35+1 -> 46187 | DM35: =+DE35+1 -> 46188 | DU35: =+DM35+1 -> 46189 | EC35: =+DU35+1 -> 46190 | EK35: =+EC35+1 -> 46191 | ES35: =+EK35+1 -> 46192 | FA35: =+ES35+1 -> 46193 | FI35: =+FA35+1 -> 46194 | FQ35: =+FI35+1 -> 46195 | FY35: =+FQ35+1 -> 46196 | GG35: =+FY35+1 -> 46197 | GO35: =+GG35+1 -> 46198 | GW35: =+GO35+1 -> 46199 | HE35: =+GW35+1 -> 46200 | HM35: =+HE35+1 -> 46201 | HU35: =+HM35+1 -> 46202 | IC35: =+HU35+1 -> 46203
C36: CUICHAPA 359 | D36: CERRADO | E36: =+E35 -> 46174 | M36: =+E36+1 -> 46175 | N36: 1 | U36: =+M36+1 -> 46176 | AC36: =+U36+1 -> 46177 | AK36: =+AC36+1 -> 46178 | AS36: =+AK36+1 -> 46179 | BA36: =+AS36+1 -> 46180 | BB36: 1 | BI36: =+BA36+1 -> 46181 | BJ36: 4 | BQ36: =+BI36+1 -> 46182 | BY36: =+BQ36+1 -> 46183 | CG36: =+BY36+1 -> 46184 | CO36: =+CG36+1 -> 46185 | CP36: 1 | CW36: =+CO36+1 -> 46186 | CX36: 1 | DE36: =+CW36+1 -> 46187 | DM36: =+DE36+1 -> 46188 | DU36: =+DM36+1 -> 46189 | EC36: =+DU36+1 -> 46190 | EK36: =+EC36+1 -> 46191 | ES36: =+EK36+1 -> 46192 | FA36: =+ES36+1 -> 46193 | FI36: =+FA36+1 -> 46194 | FQ36: =+FI36+1 -> 46195 | FY36: =+FQ36+1 -> 46196 | GG36: =+FY36+1 -> 46197 | GO36: =+GG36+1 -> 46198 | GW36: =+GO36+1 -> 46199 | HE36: =+GW36+1 -> 46200 | HM36: =+HE36+1 -> 46201 | HU36: =+HM36+1 -> 46202 | IC36: =+HU36+1 -> 46203
C37: CUICHAPA 363 | D37: OPERANDO | E37: =+E36 -> 46174 | F37: 1 | M37: =+E37+1 -> 46175 | N37: 1 | U37: =+M37+1 -> 46176 | AC37: =+U37+1 -> 46177 | AD37: 1 | AK37: =+AC37+1 -> 46178 | AL37: 1 | AS37: =+AK37+1 -> 46179 | AT37: 1 | BA37: =+AS37+1 -> 46180 | BB37: 1 | BI37: =+BA37+1 -> 46181 | BJ37: 1 | BQ37: =+BI37+1 -> 46182 | BR37: 1 | BY37: =+BQ37+1 -> 46183 | BZ37: 1 | CG37: =+BY37+1 -> 46184 | CH37: 1 | CO37: =+CG37+1 -> 46185 | CP37: 1 | CW37: =+CO37+1 -> 46186 | CX37: 1 | DE37: =+CW37+1 -> 46187 | DF37: 1 | DM37: =+DE37+1 -> 46188 | DU37: =+DM37+1 -> 46189 | EC37: =+DU37+1 -> 46190 | EK37: =+EC37+1 -> 46191 | ES37: =+EK37+1 -> 46192 | FA37: =+ES37+1 -> 46193 | FI37: =+FA37+1 -> 46194 | FQ37: =+FI37+1 -> 46195 | FY37: =+FQ37+1 -> 46196 | GG37: =+FY37+1 -> 46197 | GO37: =+GG37+1 -> 46198 | GW37: =+GO37+1 -> 46199 | HE37: =+GW37+1 -> 46200 | HM37: =+HE37+1 -> 46201 | HU37: =+HM37+1 -> 46202 | IC37: =+HU37+1 -> 46203
C38: CUICHAPA 364 | D38: OPERANDO | E38: =+E37 -> 46174 | F38: 1 | M38: =+E38+1 -> 46175 | N38: 1 | U38: =+M38+1 -> 46176 | V38: 1 | AC38: =+U38+1 -> 46177 | AK38: =+AC38+1 -> 46178 | AS38: =+AK38+1 -> 46179 | BA38: =+AS38+1 -> 46180 | BI38: =+BA38+1 -> 46181 | BJ38: 1 | BQ38: =+BI38+1 -> 46182 | BY38: =+BQ38+1 -> 46183 | CG38: =+BY38+1 -> 46184 | CO38: =+CG38+1 -> 46185 | CW38: =+CO38+1 -> 46186 | CX38: 1 | DE38: =+CW38+1 -> 46187 | DM38: =+DE38+1 -> 46188 | DU38: =+DM38+1 -> 46189 | EC38: =+DU38+1 -> 46190 | EK38: =+EC38+1 -> 46191 | ES38: =+EK38+1 -> 46192 | FA38: =+ES38+1 -> 46193 | FI38: =+FA38+1 -> 46194 | FQ38: =+FI38+1 -> 46195 | FY38: =+FQ38+1 -> 46196 | GG38: =+FY38+1 -> 46197 | GO38: =+GG38+1 -> 46198 | GW38: =+GO38+1 -> 46199 | HE38: =+GW38+1 -> 46200 | HM38: =+HE38+1 -> 46201 | HU38: =+HM38+1 -> 46202 | IC38: =+HU38+1 -> 46203
C39: CUICHAPA 367 | D39: OPERANDO | E39: =+E38 -> 46174 | F39: 1 | M39: =+E39+1 -> 46175 | N39: 1 | U39: =+M39+1 -> 46176 | AC39: =+U39+1 -> 46177 | AD39: 1 | AK39: =+AC39+1 -> 46178 | AL39: 1 | AS39: =+AK39+1 -> 46179 | AT39: 1 | BA39: =+AS39+1 -> 46180 | BB39: 1 | BI39: =+BA39+1 -> 46181 | BJ39: 1 | BQ39: =+BI39+1 -> 46182 | BR39: 1 | BY39: =+BQ39+1 -> 46183 | BZ39: 1 | CG39: =+BY39+1 -> 46184 | CO39: =+CG39+1 -> 46185 | CP39: 1 | CW39: =+CO39+1 -> 46186 | CX39: 1 | DE39: =+CW39+1 -> 46187 | DF39: 1 | DM39: =+DE39+1 -> 46188 | DU39: =+DM39+1 -> 46189 | EC39: =+DU39+1 -> 46190 | EK39: =+EC39+1 -> 46191 | ES39: =+EK39+1 -> 46192 | FA39: =+ES39+1 -> 46193 | FI39: =+FA39+1 -> 46194 | FQ39: =+FI39+1 -> 46195 | FY39: =+FQ39+1 -> 46196 | GG39: =+FY39+1 -> 46197 | GO39: =+GG39+1 -> 46198 | GW39: =+GO39+1 -> 46199 | HE39: =+GW39+1 -> 46200 | HM39: =+HE39+1 -> 46201 | HU39: =+HM39+1 -> 46202 | IC39: =+HU39+1 -> 46203
C40: CUICHAPA 373 | D40: OPERANDO | E40: =+E39 -> 46174 | F40: 1 | M40: =+E40+1 -> 46175 | N40: 1 | U40: =+M40+1 -> 46176 | AC40: =+U40+1 -> 46177 | AD40: 1 | AK40: =+AC40+1 -> 46178 | AL40: 1 | AS40: =+AK40+1 -> 46179 | BA40: =+AS40+1 -> 46180 | BB40: 1 | BI40: =+BA40+1 -> 46181 | BJ40: 1 | BQ40: =+BI40+1 -> 46182 | BY40: =+BQ40+1 -> 46183 | BZ40: 1 | CG40: =+BY40+1 -> 46184 | CH40: 1 | CO40: =+CG40+1 -> 46185 | CW40: =+CO40+1 -> 46186 | CX40: 1 | DE40: =+CW40+1 -> 46187 | DF40: 1 | DM40: =+DE40+1 -> 46188 | DU40: =+DM40+1 -> 46189 | EC40: =+DU40+1 -> 46190 | EK40: =+EC40+1 -> 46191 | ES40: =+EK40+1 -> 46192 | FA40: =+ES40+1 -> 46193 | FI40: =+FA40+1 -> 46194 | FQ40: =+FI40+1 -> 46195 | FY40: =+FQ40+1 -> 46196 | GG40: =+FY40+1 -> 46197 | GO40: =+GG40+1 -> 46198 | GW40: =+GO40+1 -> 46199 | HE40: =+GW40+1 -> 46200 | HM40: =+HE40+1 -> 46201 | HU40: =+HM40+1 -> 46202 | IC40: =+HU40+1 -> 46203
...

Sheet Graficos
B3: Pozos Operando
A4: Fecha | B4: Abiertos | C4: Cerrados | E4: Supervision | H4: Nivel FT | J4: Trabajo de Pozo | L4: Drenar Lineas | N4: Medicion BS2 | P4: Aforo FT | R4: Aperturas Interm.
A5: 46082 | B5: 28 | C5: 6 | E5: =+ABRIL!F54 -> 29 | H5: =+ABRIL!G54 -> 29 | J5: =+ABRIL!H54 -> 0 | L5: =+ABRIL!I54 -> 0 | N5: =+ABRIL!J54 -> 0 | P5: =+ABRIL!K54 -> 0 | R5: =+ABRIL!L54 -> 0
A6: 46083 | B6: 28 | C6: 6 | E6: =+ABRIL!N54 -> 37 | H6: =+ABRIL!O54 -> 23 | J6: =+ABRIL!P54 -> 0 | L6: =+ABRIL!Q54 -> 0 | N6: =+ABRIL!R54 -> 0 | P6: =+ABRIL!S54 -> 0 | R6: =+ABRIL!T54 -> 0
A7: 46084 | B7: 28 | C7: 6 | E7: =+ABRIL!V54 -> 18 | H7: =+ABRIL!W54 -> 18 | J7: =+ABRIL!X54 -> 0 | L7: =+ABRIL!Y54 -> 0 | N7: =+ABRIL!Z54 -> 0 | P7: =+ABRIL!AA54 -> 0 | R7: =+ABRIL!AB54 -> 0
A8: 46085 | B8: 28 | C8: 6 | E8: =+ABRIL!AD54 -> 27 | H8: =+ABRIL!AE54 -> 29 | J8: =+ABRIL!AF54 -> 0 | L8: =+ABRIL!AG54 -> 0 | N8: =+ABRIL!AH54 -> 0 | P8: =+ABRIL!AI54 -> 0 | R8: =+ABRIL!AJ54 -> 0
A9: 46086 | B9: 28 | C9: 6 | E9: =+ABRIL!AL54 -> 26 | H9: =+ABRIL!AM54 -> 35 | J9: =+ABRIL!AN54 -> 0 | L9: =+ABRIL!AO54 -> 0 | N9: =+ABRIL!AP54 -> 0 | P9: =+ABRIL!AQ54 -> 0 | R9: =+ABRIL!AR54 -> 0
A10: 46087 | B10: 28 | C10: 6 | E10: =+ABRIL!AT54 -> 24 | H10: =+ABRIL!AU54 -> 26 | J10: =+ABRIL!AV54 -> 0 | L10: =+ABRIL!AW54 -> 0 | N10: =+ABRIL!AX54 -> 0 | P10: =+ABRIL!AY54 -> 0 | R10: =+ABRIL!AZ54 -> 0
A11: 46088 | B11: 28 | C11: 6 | E11: =+ABRIL!BB54 -> 25 | H11: =+ABRIL!BC54 -> 18 | J11: =+ABRIL!BD54 -> 0 | L11: =+ABRIL!BE54 -> 0 | N11: =+ABRIL!BF54 -> 0 | P11: =+ABRIL!BG54 -> 0 | R11: =+ABRIL!BH54 -> 0
A12: 46089 | B12: 28 | C12: 6 | E12: =+ABRIL!BJ54 -> 23 | H12: =+ABRIL!BK54 -> 19 | J12: =+ABRIL!BL54 -> 0 | L12: =+ABRIL!BM54 -> 0 | N12: =+ABRIL!BN54 -> 0 | P12: =+ABRIL!BO54 -> 0 | R12: =+ABRIL!BP54 -> 0
A13: 46090 | B13: 28 | C13: 6 | E13: =+ABRIL!BR54 -> 27 | H13: =+ABRIL!BS54 -> 30 | J13: =+ABRIL!BT54 -> 0 | L13: =+ABRIL!BU54 -> 0 | N13: =+ABRIL!BV54 -> 0 | P13: =+ABRIL!BW54 -> 0 | R13: =+ABRIL!BX54 -> 0
A14: 46091 | B14: 28 | C14: 6 | E14: =+ABRIL!BZ54 -> 27 | H14: =+ABRIL!CA54 -> 30 | J14: =+ABRIL!CB54 -> 0 | L14: =+ABRIL!CC54 -> 0 | N14: =+ABRIL!CD54 -> 0 | P14: =+ABRIL!CE54 -> 0 | R14: =+ABRIL!CF54 -> 0
A15: 46092 | B15: 28 | C15: 6 | E15: =+ABRIL!CH54 -> 27 | H15: =+ABRIL!CI54 -> 25 | J15: =+ABRIL!CJ54 -> 0 | L15: =+ABRIL!CK54 -> 0 | N15: =+ABRIL!CL54 -> 0 | P15: =+ABRIL!CM54 -> 0 | R15: =+ABRIL!CN54 -> 0
A16: 46093 | B16: 28 | C16: 6 | E16: =+ABRIL!CP54 -> 23 | H16: =+ABRIL!CQ54 -> 23 | J16: =+ABRIL!CR54 -> 0 | L16: =+ABRIL!CS54 -> 0 | N16: =+ABRIL!CT54 -> 0 | P16: =+ABRIL!CU54 -> 0 | R16: =+ABRIL!CV54 -> 0
A17: 46094 | B17: 28 | C17: 6 | E17: =+ABRIL!CX54 -> 30 | H17: =+ABRIL!CY54 -> 25 | J17: =+ABRIL!CZ54 -> 0 | L17: =+ABRIL!DA54 -> 0 | N17: =+ABRIL!DB54 -> 0 | P17: =+ABRIL!DC54 -> 0 | R17: =+ABRIL!DD54 -> 0
A18: 46095 | B18: 28 | C18: 6 | E18: =+ABRIL!DF54 -> 30 | H18: =+ABRIL!DG54 -> 26 | J18: =+ABRIL!DH54 -> 0 | L18: =+ABRIL!DI54 -> 0 | N18: =+ABRIL!DJ54 -> 0 | P18: =+ABRIL!DK54 -> 0 | R18: =+ABRIL!DL54 -> 0
A19: 46096 | B19: 28 | C19: 6 | E19: =+ABRIL!DN54 -> 18 | H19: =+ABRIL!DO54 -> 13 | J19: =+ABRIL!DP54 -> 0 | L19: =+ABRIL!DQ54 -> 0 | N19: =+ABRIL!DR54 -> 0 | P19: =+ABRIL!DS54 -> 0 | R19: =+ABRIL!DT54 -> 0
A20: 46097 | B20: 28 | C20: 6 | E20: =+ABRIL!DV54 -> 13 | H20: =+ABRIL!DW54 -> 14 | J20: =+ABRIL!DX54 -> 0 | L20: =+ABRIL!DY54 -> 0 | N20: =+ABRIL!DZ54 -> 0 | P20: =+ABRIL!EA54 -> 0 | R20: =+ABRIL!EB54 -> 0
A21: 46098 | B21: 28 | C21: 6 | E21: =+ABRIL!ED54 -> 18 | H21: =+ABRIL!EE54 -> 17 | J21: =+ABRIL!EF54 -> 0 | L21: =+ABRIL!EG54 -> 0 | N21: =+ABRIL!EH54 -> 0 | P21: =+ABRIL!EI54 -> 0 | R21: =+ABRIL!EJ54 -> 0
A22: 46099 | B22: 28 | C22: 6 | E22: =+ABRIL!EL54 -> 17 | H22: =+ABRIL!EM54 -> 14 | J22: =+ABRIL!EN54 -> 0 | L22: =+ABRIL!EO54 -> 0 | N22: =+ABRIL!EP54 -> 0 | P22: =+ABRIL!EQ54 -> 0 | R22: =+ABRIL!ER54 -> 0 | AH22: 21
A23: 46100 | B23: 28 | C23: 6 | E23: =+ABRIL!ET54 -> 15 | H23: =+ABRIL!EU54 -> 13 | J23: =+ABRIL!EV54 -> 0 | L23: =+ABRIL!EW54 -> 0 | N23: =+ABRIL!EX54 -> 0 | P23: =+ABRIL!EY54 -> 0 | R23: =+ABRIL!EZ54 -> 0 | AT23: 29
A24: 46101 | B24: 28 | C24: 6 | E24: =+ABRIL!FB54 -> 0 | H24: =+ABRIL!FC54 -> 0 | J24: =+ABRIL!FD54 -> 0 | L24: =+ABRIL!FE54 -> 0 | N24: =+ABRIL!FF54 -> 0 | P24: =+ABRIL!FG54 -> 0 | R24: =+ABRIL!FH54 -> 0
A25: 46102 | B25: 28 | C25: 6 | E25: =+ABRIL!FJ54 -> 0 | H25: =+ABRIL!FK54 -> 0 | J25: =+ABRIL!FL54 -> 0 | L25: =+ABRIL!FM54 -> 0 | N25: =+ABRIL!FN54 -> 0 | P25: =+ABRIL!FO54 -> 0 | R25: =+ABRIL!FP54 -> 0
A26: 46103 | B26: 28 | C26: 6 | E26: =+ABRIL!FR54 -> 0 | H26: =+ABRIL!FS54 -> 0 | J26: =+ABRIL!FT54 -> 0 | L26: =+ABRIL!FU54 -> 0 | N26: =+ABRIL!FV54 -> 0 | P26: =+ABRIL!FW54 -> 0 | R26: =+ABRIL!FX54 -> 0
A27: 46104 | B27: 28 | C27: 6 | E27: =+ABRIL!FZ54 -> 0 | H27: =+ABRIL!GA54 -> 0 | J27: =+ABRIL!GB54 -> 0 | L27: =+ABRIL!GC54 -> 0 | N27: =+ABRIL!GD54 -> 0 | P27: =+ABRIL!GE54 -> 0 | R27: =+ABRIL!GF54 -> 0
A28: 46105 | B28: 28 | C28: 6 | E28: =+ABRIL!GH54 -> 0 | H28: =+ABRIL!GI54 -> 0 | J28: =+ABRIL!GJ54 -> 0 | L28: =+ABRIL!GK54 -> 0 | N28: =+ABRIL!GL54 -> 0 | P28: =+ABRIL!GM54 -> 0 | R28: =+ABRIL!GN54 -> 0
A29: 46106 | B29: 28 | C29: 6 | E29: =+ABRIL!GP54 -> 0 | H29: =+ABRIL!GQ54 -> 0 | J29: =+ABRIL!GR54 -> 0 | L29: =+ABRIL!GS54 -> 0 | N29: =+ABRIL!GT54 -> 0 | P29: =+ABRIL!GU54 -> 0 | R29: =+ABRIL!GV54 -> 0
A30: 46107 | B30: 28 | C30: 6 | E30: =+ABRIL!GX54 -> 0 | H30: =+ABRIL!GY54 -> 0 | J30: =+ABRIL!GZ54 -> 0 | L30: =+ABRIL!HA54 -> 0 | N30: =+ABRIL!HB54 -> 0 | P30: =+ABRIL!HC54 -> 0 | R30: =+ABRIL!HD54 -> 0
A31: 46108 | B31: 28 | C31: 6 | E31: =+ABRIL!HF54 -> 0 | H31: =+ABRIL!HG54 -> 0 | J31: =+ABRIL!HH54 -> 0 | L31: =+ABRIL!HI54 -> 0 | N31: =+ABRIL!HJ54 -> 0 | P31: =+ABRIL!HK54 -> 0 | R31: =+ABRIL!HL54 -> 0
A32: 46109 | B32: 28 | C32: 6 | E32: =+ABRIL!HN54 -> 0 | H32: =+ABRIL!HO54 -> 0 | J32: =+ABRIL!HP54 -> 0 | L32: =+ABRIL!HQ54 -> 0 | N32: =+ABRIL!HR54 -> 0 | P32: =+ABRIL!HS54 -> 0 | R32: =+ABRIL!HT54 -> 0
A33: 46110 | B33: 28 | C33: 6 | E33: =+ABRIL!HV54 -> 0 | H33: =+ABRIL!HW54 -> 0 | J33: =+ABRIL!HX54 -> 0 | L33: =+ABRIL!HY54 -> 0 | N33: =+ABRIL!HZ54 -> 0 | P33: =+ABRIL!IA54 -> 0 | R33: =+ABRIL!IB54 -> 0
A34: 46111 | B34: 28 | C34: 6 | E34: =+ABRIL!ID54 -> 0 | H34: =+ABRIL!IE54 -> 0 | J34: =+ABRIL!IF54 -> 0 | L34: =+ABRIL!IG54 -> 0 | N34: =+ABRIL!HZ54 -> 0 | P34: =+ABRIL!II54 -> 0 | R34: =+ABRIL!IJ54 -> 0
A35: 46112 | B35: 28 | C35: 6 | E35: =+ABRIL!IL54 -> 0 | H35: =+ABRIL!IM54 -> 0 | J35: =+ABRIL!IN54 -> 0 | L35: =+ABRIL!IO54 -> 0 | N35: =+ABRIL!IP54 -> 0 | P35: =+ABRIL!IQ54 -> 0 | R35: =+ABRIL!IR54 -> 0
A37: PROMEDIO | E37: =AVERAGE(E5:E35) -> 14.645161 | H37: =AVERAGE(H5:H35) -> 13.774194 | J37: =AVERAGE(J5:J35) -> 0 | L37: =AVERAGE(L5:L35) -> 0 | N37: =AVERAGE(N5:N35) -> 0 | P37: =AVERAGE(P5:P35) -> 0 | R37: =AVERAGE(R5:R35) -> 0
B72: PROMEDIO MENSUALES
B73: ACTIVIDADES | G73: Real
B74: Supervisión y monitoreo de condiciones operativas a pozos | G74: =+E37 -> 14.645161
B75: Aforo/Medición a pozo (batería-FT) | G75: =+P37 -> 0
B76: Drenar líquidos en red de BN | G76: =+L37 -> 0
B77: Trabajo a pozo | G77: =+J37 -> 0

Sheet GVMetadata
A2: GVData0 | B2: (end)
